#VRML_SIM R2022a utf8
WorldInfo {
}
Viewpoint {
  orientation -0.17857164600875444 0.27195456335392526 0.9455965750322385 1.213932376090762
  position -0.8774352144947473 -14.110428108756143 9.56004008495989
}
TexturedBackground {
}
TexturedBackgroundLight {
}
Robot {
  translation 5.879684794957319 -0.028281278224815763 3.660008111606294
  rotation 0.8184813593418907 -0.5734906805779256 0.03459340544263732 0.07929369110734787
  children [
    DEF torso Shape {
      appearance PBRAppearance {
        baseColor 0.6 0.6 1
        metalness 0
      }
      geometry Box {
        size 1 1 0.2
      }
    }
    DEF wheel HingeJoint {
      jointParameters HingeJointParameters {
        position 32.79989963310647
        axis 0 1 0
        anchor -0.3 -0.577883 -0.0631591
      }
      device [
        RotationalMotor {
          name "motor1"
        }
      ]
      endPoint Solid {
        translation -0.3 -0.577883 -0.0631591
        rotation 0.6432003579397373 -0.54972322889533 -0.5330081342335089 4.3130277867936115
        children [
          DEF wheel_body Shape {
            appearance Asphalt {
            }
            geometry Cylinder {
              height 0.2
              radius 0.18
            }
          }
        ]
        boundingObject USE wheel_body
        physics DEF phy1 Physics {
          mass 1
        }
        linearVelocity -3.593741324514176e-06 -4.74136290139259e-06 -5.35557005605365e-07
        angularVelocity -1.963981526661563e-09 -1.3207859803767936e-06 3.782145625609974e-07
      }
    }
    DEF wheel HingeJoint {
      jointParameters HingeJointParameters {
        position 32.796673834093276
        axis 0 1 0
        anchor 0.3 -0.577883 -0.0631591
      }
      device [
        RotationalMotor {
          name "motor2"
        }
      ]
      endPoint Solid {
        translation 0.3 -0.577883 -0.0631591
        rotation 0.6444382484062272 -0.5489754540523668 -0.5322830965183014 4.314799877980264
        children [
          DEF wheel_body Shape {
            appearance Asphalt {
            }
            geometry Cylinder {
              height 0.2
              radius 0.18
            }
          }
        ]
        name "solid(1)"
        boundingObject USE wheel_body
        physics DEF phy1 Physics {
          mass 1
        }
        linearVelocity -3.597358433622421e-06 -4.467753346299116e-06 -4.6376552074889373e-07
        angularVelocity -2.076184781364232e-09 -1.2935278843673765e-06 3.7998391756356915e-07
      }
    }
    DEF wheel HingeJoint {
      jointParameters HingeJointParameters {
        position 32.79913126213988
        axis 0 1 0
        anchor 0.3 0.577883 -0.0631591
      }
      device [
        RotationalMotor {
          name "motor3"
        }
      ]
      endPoint Solid {
        translation 0.3 0.577883 -0.0631591
        rotation 0.6434952386096316 -0.5495453224992094 -0.5328356373272841 4.313450109821714
        children [
          DEF wheel_body Shape {
            appearance Asphalt {
            }
            geometry Cylinder {
              height 0.2
              radius 0.18
            }
          }
        ]
        name "solid(2)"
        boundingObject USE wheel_body
        physics DEF phy1 Physics {
          mass 1
        }
        linearVelocity -4.13243738624192e-06 -4.469450103157004e-06 -4.7245472848089557e-07
        angularVelocity -5.062004044921761e-09 -5.92154304581815e-07 4.2550761241158027e-07
      }
    }
    DEF wheel HingeJoint {
      jointParameters HingeJointParameters {
        position 32.800230950381
        axis 0 1 0
        anchor -0.3 0.577883 -0.0631591
      }
      device [
        RotationalMotor {
          name "motor4"
        }
      ]
      endPoint Solid {
        translation -0.3 0.577883 -0.0631591
        rotation 0.643073203094021 -0.5497999006028274 -0.5330824746317561 4.312845641289665
        children [
          DEF wheel_body Shape {
            appearance Asphalt {
            }
            geometry Cylinder {
              height 0.2
              radius 0.18
            }
          }
        ]
        name "solid(3)"
        boundingObject USE wheel_body
        physics DEF phy1 Physics {
          mass 1
        }
        linearVelocity -4.128813936143045e-06 -4.743051478069307e-06 -5.443662885227238e-07
        angularVelocity -1.8459262578325694e-09 -1.3548187168272889e-06 3.760051967997146e-07
      }
    }
  ]
  boundingObject USE torso
  physics USE phy1
  controller "my_controller"
  linearVelocity -3.868766500379373e-06 -4.606266451660624e-06 -5.043502710577741e-07
  angularVelocity -7.055363127301557e-09 -1.198901115370299e-07 4.561601980051152e-07
}
UnevenTerrain {
}
